2018-02-22 12:21:04,665 ERROR: Exception on /robots.txt [GET] [in /Users/justencracraft/source/python/microblog/venv/lib/python3.6/site-packages/flask/app.py:1560]
Traceback (most recent call last):
  File "/Users/justencracraft/source/python/microblog/venv/lib/python3.6/site-packages/flask/app.py", line 1612, in full_dispatch_request
    rv = self.dispatch_request()
  File "/Users/justencracraft/source/python/microblog/venv/lib/python3.6/site-packages/flask/app.py", line 1590, in dispatch_request
    self.raise_routing_exception(req)
  File "/Users/justencracraft/source/python/microblog/venv/lib/python3.6/site-packages/flask/app.py", line 1573, in raise_routing_exception
    raise request.routing_exception
  File "/Users/justencracraft/source/python/microblog/venv/lib/python3.6/site-packages/flask/ctx.py", line 294, in match_request
    self.url_adapter.match(return_rule=True)
  File "/Users/justencracraft/source/python/microblog/venv/lib/python3.6/site-packages/werkzeug/routing.py", line 1581, in match
    raise NotFound()
werkzeug.exceptions.NotFound: 404 Not Found: The requested URL was not found on the server.  If you entered the URL manually please check your spelling and try again.

During handling of the above exception, another exception occurred:

Traceback (most recent call last):
  File "/Users/justencracraft/source/python/microblog/venv/lib/python3.6/site-packages/flask/app.py", line 1982, in wsgi_app
    response = self.full_dispatch_request()
  File "/Users/justencracraft/source/python/microblog/venv/lib/python3.6/site-packages/flask/app.py", line 1614, in full_dispatch_request
    rv = self.handle_user_exception(e)
  File "/Users/justencracraft/source/python/microblog/venv/lib/python3.6/site-packages/flask/app.py", line 1512, in handle_user_exception
    return self.handle_http_exception(e)
  File "/Users/justencracraft/source/python/microblog/venv/lib/python3.6/site-packages/flask/app.py", line 1471, in handle_http_exception
    return handler(e)
  File "/Users/justencracraft/source/python/microblog/app/errors.py", line 6, in not_found_error
    return render_template('404.html'), 404
  File "/Users/justencracraft/source/python/microblog/venv/lib/python3.6/site-packages/flask/templating.py", line 134, in render_template
    context, ctx.app)
  File "/Users/justencracraft/source/python/microblog/venv/lib/python3.6/site-packages/flask/templating.py", line 116, in _render
    rv = template.render(context)
  File "/Users/justencracraft/source/python/microblog/venv/lib/python3.6/site-packages/jinja2/asyncsupport.py", line 76, in render
    return original_render(self, *args, **kwargs)
  File "/Users/justencracraft/source/python/microblog/venv/lib/python3.6/site-packages/jinja2/environment.py", line 1008, in render
    return self.environment.handle_exception(exc_info, True)
  File "/Users/justencracraft/source/python/microblog/venv/lib/python3.6/site-packages/jinja2/environment.py", line 780, in handle_exception
    reraise(exc_type, exc_value, tb)
  File "/Users/justencracraft/source/python/microblog/venv/lib/python3.6/site-packages/jinja2/_compat.py", line 37, in reraise
    raise value.with_traceback(tb)
  File "/Users/justencracraft/source/python/microblog/app/templates/base.html", line 33, in template
    {% endfor %} {% endif %} {% endwith %} {# application content needs to be provided in the app_content block #} {% block app_content %}{% endblock %}
  File "/Users/justencracraft/source/python/microblog/venv/lib/python3.6/site-packages/jinja2/environment.py", line 1005, in render
    return concat(self.root_render_func(self.new_context(vars)))
  File "/Users/justencracraft/source/python/microblog/app/templates/404.html", line 1, in top-level template code
    {% extends 'base.html' %} {% block app_content %}
  File "/Users/justencracraft/source/python/microblog/venv/lib/python3.6/site-packages/jinja2/environment.py", line 780, in handle_exception
    reraise(exc_type, exc_value, tb)
  File "/Users/justencracraft/source/python/microblog/venv/lib/python3.6/site-packages/jinja2/_compat.py", line 37, in reraise
    raise value.with_traceback(tb)
  File "/Users/justencracraft/source/python/microblog/app/templates/base.html", line 33, in template
    {% endfor %} {% endif %} {% endwith %} {# application content needs to be provided in the app_content block #} {% block app_content %}{% endblock %}
  File "/Users/justencracraft/source/python/microblog/venv/lib/python3.6/site-packages/jinja2/environment.py", line 497, in _parse
    return Parser(self, source, name, encode_filename(filename)).parse()
  File "/Users/justencracraft/source/python/microblog/venv/lib/python3.6/site-packages/jinja2/parser.py", line 901, in parse
    result = nodes.Template(self.subparse(), lineno=1)
  File "/Users/justencracraft/source/python/microblog/venv/lib/python3.6/site-packages/jinja2/parser.py", line 883, in subparse
    rv = self.parse_statement()
  File "/Users/justencracraft/source/python/microblog/venv/lib/python3.6/site-packages/jinja2/parser.py", line 130, in parse_statement
    return getattr(self, 'parse_' + self.stream.current.value)()
  File "/Users/justencracraft/source/python/microblog/venv/lib/python3.6/site-packages/jinja2/parser.py", line 268, in parse_block
    node.body = self.parse_statements(('name:endblock',), drop_needle=True)
  File "/Users/justencracraft/source/python/microblog/venv/lib/python3.6/site-packages/jinja2/parser.py", line 170, in parse_statements
    self.fail_eof(end_tokens)
  File "/Users/justencracraft/source/python/microblog/venv/lib/python3.6/site-packages/jinja2/parser.py", line 104, in fail_eof
    return self._fail_ut_eof(None, stack, lineno)
  File "/Users/justencracraft/source/python/microblog/venv/lib/python3.6/site-packages/jinja2/parser.py", line 90, in _fail_ut_eof
    self.fail(' '.join(message), lineno)
  File "/Users/justencracraft/source/python/microblog/venv/lib/python3.6/site-packages/jinja2/parser.py", line 59, in fail
    raise exc(msg, lineno, self.name, self.filename)
jinja2.exceptions.TemplateSyntaxError: Unexpected end of template. Jinja was looking for the following tags: 'endblock'. The innermost block that needs to be closed is 'block'.
2018-02-22 13:14:05,209 INFO: Microblog startup [in /Users/justencracraft/source/python/microblog/app/__init__.py:46]
